Workbook

Sheet Sheet1
A1: NAMA | B1: NIP | C1: bulan lahir | D1: tahunlahir | E1: Golongan TMT | F1: Jabatan | G1: Pendidikan | H1: golongan | I1: id_pegawai | J1: nama_pegawai | K1: nip_pegawai | L1: jenis_kelamin | N1: bidang | O1: status | P1: jenis_jabatan | Q1: jabatan | R1: gelar | S1: nomor_hp | T1: foto
A2: SRI WIDAYANTI, S.H., M.M. | B2: 196704231993032001 | C2: 4 | D2: 1967 | E2: IV/d, TMT 01-10-2024 | F2: Kepala Kantor | G2: S2 | H2: =LEFT(E2, SEARCH(",",E2)-1) -> IV/d | I2: 1 | J2: =A2 -> SRI WIDAYANTI, S.H., M.M. | K2: =""&B2 -> 196704231993032001 | L2: =LEFT(RIGHT(K2, 4), 1) -> 2 | N2: 6 | O2: 1 | P2: =INDEX(Sheet2!A:A, MATCH(F2, Sheet2!B:B, 0)) -> 1 | Q2: 1 | R2: =INDEX(Sheet3!A:A, MATCH(G2, Sheet3!B:B, 0)) -> 3 | S2: 08123 | T2: =CONCATENATE(K2, ".jpg") -> 196704231993032001.jpg
A3: IWAN SETYO PRIHATIN, SH., M.A.P | B3: 197708311997031000 | C3: 8 | D3: 1977 | E3: IV/b, TMT 01-10-2019 | F3: Kepala Bagian Tata Usaha | G3: S2 | H3: =LEFT(E3, SEARCH(",",E3)-1) -> IV/b | I3: 2 | J3: =A3 -> IWAN SETYO PRIHATIN, SH., M.A.P | K3: =""&B3 -> 197708311997031000 | L3: =LEFT(RIGHT(K3, 4), 1) -> 1 | N3: 6 | O3: 1 | P3: =INDEX(Sheet2!A:A, MATCH(F3, Sheet2!B:B, 0)) -> 2 | Q3: 1 | R3: =INDEX(Sheet3!A:A, MATCH(G3, Sheet3!B:B, 0)) -> 3 | S3: 08123 | T3: =CONCATENATE(K3, ".jpg") -> 197708311997031000.jpg
A4: ARI WIBAWA , SE, M.AP. | B4: 198511072015031001 | C4: 11 | D4: 1985 | E4: III/d, TMT 01-10-2025 | F4: Kasubag Kepegawaian | G4: S2 | H4: =LEFT(E4, SEARCH(",",E4)-1) -> III/d | I4: 3 | J4: =A4 -> ARI WIBAWA , SE, M.AP. | K4: =""&B4 -> 198511072015031001 | L4: =LEFT(RIGHT(K4, 4), 1) -> 1 | N4: 6 | O4: 1 | P4: =INDEX(Sheet2!A:A, MATCH(F4, Sheet2!B:B, 0)) -> 3 | Q4: 1 | R4: =INDEX(Sheet3!A:A, MATCH(G4, Sheet3!B:B, 0)) -> 3 | S4: 08123 | T4: =CONCATENATE(K4, ".jpg") -> 198511072015031001.jpg
A5: JUMALI, S.I.P | B5: 1.9770107e+17 | C5: 1 | D5: 1977 | E5: III/b, TMT 01-10-2022 | F5: Analis Sumber Daya Manusia Aparatur Ahli Pertama | G5: S1 | H5: =LEFT(E5, SEARCH(",",E5)-1) -> III/b | I5: 4 | J5: =A5 -> JUMALI, S.I.P | K5: =""&B5 -> 197701072010121000 | L5: =LEFT(RIGHT(K5, 4), 1) -> 1 | N5: 6 | O5: 1 | P5: =INDEX(Sheet2!A:A, MATCH(F5, Sheet2!B:B, 0)) -> 4 | Q5: 2 | R5: =INDEX(Sheet3!A:A, MATCH(G5, Sheet3!B:B, 0)) -> 4 | S5: 08123 | T5: =CONCATENATE(K5, ".jpg") -> 197701072010121000.jpg
A6: APRIYANI, SE | B6: 1.9840407e+17 | C6: 4 | D6: 1984 | E6: III/d, TMT 01-04-2025 | F6: Penelaah Teknis Kebijakan | G6: S1 | H6: =LEFT(E6, SEARCH(",",E6)-1) -> III/d | I6: 5 | J6: =A6 -> APRIYANI, SE | K6: =""&B6 -> 198404072006042000 | L6: =LEFT(RIGHT(K6, 4), 1) -> 2 | N6: 6 | O6: 1 | P6: =INDEX(Sheet2!A:A, MATCH(F6, Sheet2!B:B, 0)) -> 5 | Q6: 2 | R6: =INDEX(Sheet3!A:A, MATCH(G6, Sheet3!B:B, 0)) -> 4 | S6: 08123 | T6: =CONCATENATE(K6, ".jpg") -> 198404072006042000.jpg
A7: DIAN KUSUMA WARDHANI,A.Md | B7: 1.9810816e+17 | C7: 8 | D7: 1981 | E7: III/c, TMT 01-11-2025 | F7: Arsiparis Penyelia | G7: DIII | H7: =LEFT(E7, SEARCH(",",E7)-1) -> III/c | I7: 6 | J7: =A7 -> DIAN KUSUMA WARDHANI,A.Md | K7: =""&B7 -> 198108162008012000 | L7: =LEFT(RIGHT(K7, 4), 1) -> 2 | N7: 6 | O7: 1 | P7: =INDEX(Sheet2!A:A, MATCH(F7, Sheet2!B:B, 0)) -> 6 | Q7: 2 | R7: =INDEX(Sheet3!A:A, MATCH(G7, Sheet3!B:B, 0)) -> 5 | S7: 08123 | T7: =CONCATENATE(K7, ".jpg") -> 198108162008012000.jpg
A8: DODY RAHMAT SHOLIHIN, S.IP, MPA | B8: 198812252019021002 | C8: 12 | D8: 1988 | E8: III/c, TMT 01-08-2025 | F8: Analis Sumber Daya Manusia Aparatur Ahli Muda | G8: S2 | H8: =LEFT(E8, SEARCH(",",E8)-1) -> III/c | I8: 7 | J8: =A8 -> DODY RAHMAT SHOLIHIN, S.IP, MPA | K8: =""&B8 -> 198812252019021002 | L8: =LEFT(RIGHT(K8, 4), 1) -> 1 | N8: 6 | O8: 1 | P8: =INDEX(Sheet2!A:A, MATCH(F8, Sheet2!B:B, 0)) -> 7 | Q8: 2 | R8: =INDEX(Sheet3!A:A, MATCH(G8, Sheet3!B:B, 0)) -> 3 | S8: 08123 | T8: =CONCATENATE(K8, ".jpg") -> 198812252019021002.jpg
A9: NOVANDA FATIH HARDANTI, S.Psi., M.Psi., Psikolog | B9: 1.995113e+17 | C9: 11 | D9: 1995 | E9: III/b, TMT 01-06-2025 | F9: Penelaah Teknis Kebijakan | G9: S2 | H9: =LEFT(E9, SEARCH(",",E9)-1) -> III/b | I9: 8 | J9: =A9 -> NOVANDA FATIH HARDANTI, S.Psi., M.Psi., Psikolog | K9: =""&B9 -> 199511302022032000 | L9: =LEFT(RIGHT(K9, 4), 1) -> 2 | N9: 6 | O9: 1 | P9: =INDEX(Sheet2!A:A, MATCH(F9, Sheet2!B:B, 0)) -> 5 | Q9: 2 | R9: =INDEX(Sheet3!A:A, MATCH(G9, Sheet3!B:B, 0)) -> 3 | S9: 08123 | T9: =CONCATENATE(K9, ".jpg") -> 199511302022032000.jpg
A10: ACHID ANUGRAHANTO, S.E. | B10: 199106142020121008 | C10: 6 | D10: 1991 | E10: III/b, TMT 01-12-2024 | F10: Penelaah Teknis Kebijakan | G10: S1 | H10: =LEFT(E10, SEARCH(",",E10)-1) -> III/b | I10: 9 | J10: =A10 -> ACHID ANUGRAHANTO, S.E. | K10: =""&B10 -> 199106142020121008 | L10: =LEFT(RIGHT(K10, 4), 1) -> 1 | N10: 6 | O10: 1 | P10: =INDEX(Sheet2!A:A, MATCH(F10, Sheet2!B:B, 0)) -> 5 | Q10: 2 | R10: =INDEX(Sheet3!A:A, MATCH(G10, Sheet3!B:B, 0)) -> 4 | S10: 08123 | T10: =CONCATENATE(K10, ".jpg") -> 199106142020121008.jpg
A11: RADEN RARA FITRI WIKANDARI, S.I.Kom. | B11: 198407092015032002 | C11: 7 | D11: 1984 | E11: III/b, TMT 01-11-2025 | F11: Pranata SDM Mahir | G11: S1 | H11: =LEFT(E11, SEARCH(",",E11)-1) -> III/b | I11: 10 | J11: =A11 -> RADEN RARA FITRI WIKANDARI, S.I.Kom. | K11: =""&B11 -> 198407092015032002 | L11: =LEFT(RIGHT(K11, 4), 1) -> 2 | N11: 6 | O11: 1 | P11: =INDEX(Sheet2!A:A, MATCH(F11, Sheet2!B:B, 0)) -> 8 | Q11: 2 | R11: =INDEX(Sheet3!A:A, MATCH(G11, Sheet3!B:B, 0)) -> 4 | S11: 08123 | T11: =CONCATENATE(K11, ".jpg") -> 198407092015032002.jpg
A12: VICTORRIANUS BAGUS WINDA KURINIAWAN, S.Si. | B12: 1.9770323e+17 | C12: 1 | D12: 1977 | E12: III/d, TMT 01-04-2026 | F12: Pengolah Data dan Informasi | G12: S1 | H12: =LEFT(E12, SEARCH(",",E12)-1) -> III/d | I12: 11 | J12: =A12 -> VICTORRIANUS BAGUS WINDA KURINIAWAN, S.Si. | K12: =""&B12 -> 197703232008011000 | L12: =LEFT(RIGHT(K12, 4), 1) -> 1 | N12: 6 | O12: 1 | P12: =INDEX(Sheet2!A:A, MATCH(F12, Sheet2!B:B, 0)) -> 9 | Q12: 2 | R12: =INDEX(Sheet3!A:A, MATCH(G12, Sheet3!B:B, 0)) -> 4 | S12: 08123 | T12: =CONCATENATE(K12, ".jpg") -> 197703232008011000.jpg
A13: MUHAMMAD ROBI SETIAWAN, S.AB. | B13: 1.9950809e+17 | C13: 8 | D13: 1995 | E13: III/b, TMT 01-12-2024 | F13: Analis Sumber Daya Manusia Aparatur Ahli Pertama | G13: S1 | H13: =LEFT(E13, SEARCH(",",E13)-1) -> III/b | I13: 12 | J13: =A13 -> MUHAMMAD ROBI SETIAWAN, S.AB. | K13: =""&B13 -> 199508092020121000 | L13: =LEFT(RIGHT(K13, 4), 1) -> 1 | N13: 6 | O13: 1 | P13: =INDEX(Sheet2!A:A, MATCH(F13, Sheet2!B:B, 0)) -> 10 | Q13: 2 | R13: =INDEX(Sheet3!A:A, MATCH(G13, Sheet3!B:B, 0)) -> 4 | S13: 08123 | T13: =CONCATENATE(K13, ".jpg") -> 199508092020121000.jpg
A14: NINIK SETYORINI, SE | B14: 1.9780422e+17 | C14: 4 | D14: 1978 | E14: III/d, TMT 01-10-2025 | F14: Kasubag Perencanaan dan Keuangan | G14: S1 | H14: =LEFT(E14, SEARCH(",",E14)-1) -> III/d | I14: 13 | J14: =A14 -> NINIK SETYORINI, SE | K14: =""&B14 -> 197804222006042000 | L14: =LEFT(RIGHT(K14, 4), 1) -> 2 | N14: 6 | O14: 1 | P14: =INDEX(Sheet2!A:A, MATCH(F14, Sheet2!B:B, 0)) -> 11 | Q14: 2 | R14: =INDEX(Sheet3!A:A, MATCH(G14, Sheet3!B:B, 0)) -> 4 | S14: 08123 | T14: =CONCATENATE(K14, ".jpg") -> 197804222006042000.jpg
A15: VIVILIA KUSUMA JAYANTIE BASUKI, S.E., M.M. | B15: 198510182014022003 | C15: 10 | D15: 1985 | E15: III/b, TMT 01-10-2025 | F15: Arsiparis Ahli Pertama | G15: S1 | H15: =LEFT(E15, SEARCH(",",E15)-1) -> III/b | I15: 14 | J15: =A15 -> VIVILIA KUSUMA JAYANTIE BASUKI, S.E., M.M. | K15: =""&B15 -> 198510182014022003 | L15: =LEFT(RIGHT(K15, 4), 1) -> 2 | N15: 6 | O15: 1 | P15: =INDEX(Sheet2!A:A, MATCH(F15, Sheet2!B:B, 0)) -> 12 | Q15: 2 | R15: =INDEX(Sheet3!A:A, MATCH(G15, Sheet3!B:B, 0)) -> 4 | S15: 08123 | T15: =CONCATENATE(K15, ".jpg") -> 198510182014022003.jpg
A16: DIYAH RACHMAWATI HASMAMY, SE | B16: 1.984052e+17 | C16: 5 | D16: 1984 | E16: III/c, TMT 01-04-2023 | F16: Penelaah Teknis Kebijakan | G16: S1 | H16: =LEFT(E16, SEARCH(",",E16)-1) -> III/c | I16: 15 | J16: =A16 -> DIYAH RACHMAWATI HASMAMY, SE | K16: =""&B16 -> 198405202015032000 | L16: =LEFT(RIGHT(K16, 4), 1) -> 2 | N16: 6 | O16: 1 | P16: =INDEX(Sheet2!A:A, MATCH(F16, Sheet2!B:B, 0)) -> 5 | Q16: 2 | R16: =INDEX(Sheet3!A:A, MATCH(G16, Sheet3!B:B, 0)) -> 4 | S16: 08123 | T16: =CONCATENATE(K16, ".jpg") -> 198405202015032000.jpg
A17: RETNO MILIASIH, S.E., M.E. | B17: 197507212006042001 | C17: 7 | D17: 1975 | E17: IV/a, TMT 01-04-2024 | F17: Analis Peng Keu APBN Madya | G17: S2 | H17: =LEFT(E17, SEARCH(",",E17)-1) -> IV/a | I17: 16 | J17: =A17 -> RETNO MILIASIH, S.E., M.E. | K17: =""&B17 -> 197507212006042001 | L17: =LEFT(RIGHT(K17, 4), 1) -> 2 | N17: 6 | O17: 1 | P17: =INDEX(Sheet2!A:A, MATCH(F17, Sheet2!B:B, 0)) -> 13 | Q17: 2 | R17: =INDEX(Sheet3!A:A, MATCH(G17, Sheet3!B:B, 0)) -> 3 | S17: 08123 | T17: =CONCATENATE(K17, ".jpg") -> 197507212006042001.jpg
A18: RIAN USMAWATI, S.E. | B18: 198306062015032002 | C18: 7 | D18: 1983 | E18: III/c, TMT 01-10-2025 | F18: Analis Peng Keu APBN Pertama | G18: S1 | H18: =LEFT(E18, SEARCH(",",E18)-1) -> III/c | I18: 17 | J18: =A18 -> RIAN USMAWATI, S.E. | K18: =""&B18 -> 198306062015032002 | L18: =LEFT(RIGHT(K18, 4), 1) -> 2 | N18: 6 | O18: 1 | P18: =INDEX(Sheet2!A:A, MATCH(F18, Sheet2!B:B, 0)) -> 14 | Q18: 2 | R18: =INDEX(Sheet3!A:A, MATCH(G18, Sheet3!B:B, 0)) -> 4 | S18: 08123 | T18: =CONCATENATE(K18, ".jpg") -> 198306062015032002.jpg
A19: EVI RISTIANA, SE | B19: 1.9860626e+17 | C19: 6 | D19: 1986 | E19: III/c, TMT 01-02-2024 | F19: Analis Peng Keu APBN Muda | G19: S1 | H19: =LEFT(E19, SEARCH(",",E19)-1) -> III/c | I19: 18 | J19: =A19 -> EVI RISTIANA, SE | K19: =""&B19 -> 198606262008012000 | L19: =LEFT(RIGHT(K19, 4), 1) -> 2 | N19: 6 | O19: 1 | P19: =INDEX(Sheet2!A:A, MATCH(F19, Sheet2!B:B, 0)) -> 15 | Q19: 2 | R19: =INDEX(Sheet3!A:A, MATCH(G19, Sheet3!B:B, 0)) -> 4 | S19: 08123 | T19: =CONCATENATE(K19, ".jpg") -> 198606262008012000.jpg
A20: FERA TRESNAWATI, M. Acc. | B20: 199302202020122004 | C20: 2 | D20: 1993 | E20: III/b, TMT 01-10-2023 | F20: Penelaah Teknis Kebijakan | G20: S2 | H20: =LEFT(E20, SEARCH(",",E20)-1) -> III/b | I20: 19 | J20: =A20 -> FERA TRESNAWATI, M. Acc. | K20: =""&B20 -> 199302202020122004 | L20: =LEFT(RIGHT(K20, 4), 1) -> 2 | N20: 6 | O20: 1 | P20: =INDEX(Sheet2!A:A, MATCH(F20, Sheet2!B:B, 0)) -> 5 | Q20: 2 | R20: =INDEX(Sheet3!A:A, MATCH(G20, Sheet3!B:B, 0)) -> 3 | S20: 08123 | T20: =CONCATENATE(K20, ".jpg") -> 199302202020122004.jpg
A21: HANDRIAN RAHMADANA, S.I.P | B21: 198903042022031003 | C21: 3 | D21: 1989 | E21: III/b, TMT 01-03-2026 | F21: Penelaah Teknis Kebijakan | G21: S1 | H21: =LEFT(E21, SEARCH(",",E21)-1) -> III/b | I21: 20 | J21: =A21 -> HANDRIAN RAHMADANA, S.I.P | K21: =""&B21 -> 198903042022031003 | L21: =LEFT(RIGHT(K21, 4), 1) -> 1 | N21: 6 | O21: 1 | P21: =INDEX(Sheet2!A:A, MATCH(F21, Sheet2!B:B, 0)) -> 5 | Q21: 2 | R21: =INDEX(Sheet3!A:A, MATCH(G21, Sheet3!B:B, 0)) -> 4 | S21: 08123 | T21: =CONCATENATE(K21, ".jpg") -> 198903042022031003.jpg
A22: AULIA TRI HASTUTI WULANDARI, A.Md.Kb.N | B22: 200006152022022001 | C22: 6 | D22: 2000 | E22: II/d, TMT 01-02-2026 | F22: Penelaah Teknis Kebijakan | G22: DIII | H22: =LEFT(E22, SEARCH(",",E22)-1) -> II/d | I22: 21 | J22: =A22 -> AULIA TRI HASTUTI WULANDARI, A.Md.Kb.N | K22: =""&B22 -> 200006152022022001 | L22: =LEFT(RIGHT(K22, 4), 1) -> 2 | N22: 6 | O22: 1 | P22: =INDEX(Sheet2!A:A, MATCH(F22, Sheet2!B:B, 0)) -> 5 | Q22: 2 | R22: =INDEX(Sheet3!A:A, MATCH(G22, Sheet3!B:B, 0)) -> 5 | S22: 08123 | T22: =CONCATENATE(K22, ".jpg") -> 200006152022022001.jpg
A23: SUHERI WIDOYOKO, SE | B23: 198004202015031002 | C23: 4 | D23: 1980 | E23: III/c, TMT 01-10-2024 | F23: Pranata Keuangan APBN Penyelia | G23: S1 | H23: =LEFT(E23, SEARCH(",",E23)-1) -> III/c | I23: 22 | J23: =A23 -> SUHERI WIDOYOKO, SE | K23: =""&B23 -> 198004202015031002 | L23: =LEFT(RIGHT(K23, 4), 1) -> 1 | N23: 6 | O23: 1 | P23: =INDEX(Sheet2!A:A, MATCH(F23, Sheet2!B:B, 0)) -> 16 | Q23: 2 | R23: =INDEX(Sheet3!A:A, MATCH(G23, Sheet3!B:B, 0)) -> 4 | S23: 08123 | T23: =CONCATENATE(K23, ".jpg") -> 198004202015031002.jpg
A24: ALIFVIA SEZA FITRIANA, A.Md.Kb.N. | B24: 2.0001009e+17 | C24: 3 | D24: 2000 | E24: II/c | F24: Pengolah Data dan Informasi | G24: DIII | H24: =E24 -> II/c | I24: 23 | J24: =A24 -> ALIFVIA SEZA FITRIANA, A.Md.Kb.N. | K24: =""&B24 -> 200010092022022000 | L24: =LEFT(RIGHT(K24, 4), 1) -> 2 | N24: 6 | O24: 1 | P24: =INDEX(Sheet2!A:A, MATCH(F24, Sheet2!B:B, 0)) -> 9 | Q24: 2 | R24: =INDEX(Sheet3!A:A, MATCH(G24, Sheet3!B:B, 0)) -> 5 | S24: 08123 | T24: =CONCATENATE(K24, ".jpg") -> 200010092022022000.jpg
A25: SUNARKO, A.Md.Pas. | B25: 199002272023211017 | C25: 2 | D25: 1990 | E25: VII | F25: Pranata Sumber Daya Manusia Aparatur Terampil | G25: DIII | H25: =E25 -> VII | I25: 24 | J25: =A25 -> SUNARKO, A.Md.Pas. | K25: =""&B25 -> 199002272023211017 | L25: =LEFT(RIGHT(K25, 4), 1) -> 1 | N25: 6 | O25: 2 | P25: =INDEX(Sheet2!A:A, MATCH(F25, Sheet2!B:B, 0)) -> 17 | Q25: 2 | R25: =INDEX(Sheet3!A:A, MATCH(G25, Sheet3!B:B, 0)) -> 5 | S25: 08123 | T25: =CONCATENATE(K25, ".jpg") -> 199002272023211017.jpg
A26: GUNAWAN, S.IP. | B26: 1.9730217e+17 | C26: 2 | D26: 1973 | E26: III/c, TMT 01-06-2025 | F26: Kasubag Umum | G26: S1 | H26: =LEFT(E26, SEARCH(",",E26)-1) -> III/c | I26: 25 | J26: =A26 -> GUNAWAN, S.IP. | K26: =""&B26 -> 197302171999021000 | L26: =LEFT(RIGHT(K26, 4), 1) -> 1 | N26: 6 | O26: 1 | P26: =INDEX(Sheet2!A:A, MATCH(F26, Sheet2!B:B, 0)) -> 18 | Q26: 1 | R26: =INDEX(Sheet3!A:A, MATCH(G26, Sheet3!B:B, 0)) -> 4 | S26: 08123 | T26: =CONCATENATE(K26, ".jpg") -> 197302171999021000.jpg
A27: SOFIKA WAHDANI WIJAYANTI, S.Sn. | B27: 1.986051e+17 | C27: 5 | D27: 1986 | E27: III/b | F27: Pranata Humas Ahli Muda | G27: S1 | H27: =E27 -> III/b | I27: 26 | J27: =A27 -> SOFIKA WAHDANI WIJAYANTI, S.Sn. | K27: =""&B27 -> 198605102018012000 | L27: =LEFT(RIGHT(K27, 4), 1) -> 2 | N27: 6 | O27: 5 | P27: =INDEX(Sheet2!A:A, MATCH(F27, Sheet2!B:B, 0)) -> 19 | Q27: 2 | R27: =INDEX(Sheet3!A:A, MATCH(G27, Sheet3!B:B, 0)) -> 4 | S27: 08123 | T27: =CONCATENATE(K27, ".jpg") -> 198605102018012000.jpg
A28: MAJID SETIYAWAN | B28: 1.9790706e+17 | C28: 7 | D28: 1979 | E28: III/b, TMT 01-04-2023 | F28: Pengelola Layanan Operasional | G28: SLTA | H28: =LEFT(E28, SEARCH(",",E28)-1) -> III/b | I28: 27 | J28: =A28 -> MAJID SETIYAWAN | K28: =""&B28 -> 197907062002121000 | L28: =LEFT(RIGHT(K28, 4), 1) -> 1 | N28: 6 | O28: 1 | P28: =INDEX(Sheet2!A:A, MATCH(F28, Sheet2!B:B, 0)) -> 20 | Q28: 2 | R28: =INDEX(Sheet3!A:A, MATCH(G28, Sheet3!B:B, 0)) -> 6 | S28: 08123 | T28: =CONCATENATE(K28, ".jpg") -> 197907062002121000.jpg
A29: RIA GUNAWAN, A.Md | B29: 1.9850709e+17 | C29: 7 | D29: 1985 | E29: III/c, TMT 01-04-2026 | F29: Pengelola Layanan Operasional | G29: DIII | H29: =LEFT(E29, SEARCH(",",E29)-1) -> III/c | I29: 28 | J29: =A29 -> RIA GUNAWAN, A.Md | K29: =""&B29 -> 198507092009121000 | L29: =LEFT(RIGHT(K29, 4), 1) -> 1 | N29: 6 | O29: 1 | P29: =INDEX(Sheet2!A:A, MATCH(F29, Sheet2!B:B, 0)) -> 20 | Q29: 2 | R29: =INDEX(Sheet3!A:A, MATCH(G29, Sheet3!B:B, 0)) -> 5 | S29: 08123 | T29: =CONCATENATE(K29, ".jpg") -> 198507092009121000.jpg
A30: HANUM SOFIA NUR MERJANTI, S.IP | B30: 199009232019022004 | C30: 9 | D30: 1990 | E30: III/b, TMT 01-10-2024 | F30: Pranata Humas Ahli Pertama | G30: S1 | H30: =LEFT(E30, SEARCH(",",E30)-1) -> III/b | I30: 29 | J30: =A30 -> HANUM SOFIA NUR MERJANTI, S.IP | K30: =""&B30 -> 199009232019022004 | L30: =LEFT(RIGHT(K30, 4), 1) -> 2 | N30: 6 | O30: 1 | P30: =INDEX(Sheet2!A:A, MATCH(F30, Sheet2!B:B, 0)) -> 21 | Q30: 2 | R30: =INDEX(Sheet3!A:A, MATCH(G30, Sheet3!B:B, 0)) -> 4 | S30: 08123 | T30: =CONCATENATE(K30, ".jpg") -> 199009232019022004.jpg
A31: MELA MELATI, S. Tr. S. I. | B31: 1.9920515e+17 | C31: 5 | D31: 1992 | E31: III/b, TMT 01-10-2024 | F31: Arsiparis Ahli Pertama | G31: S1 | H31: =LEFT(E31, SEARCH(",",E31)-1) -> III/b | I31: 30 | J31: =A31 -> MELA MELATI, S. Tr. S. I. | K31: =""&B31 -> 199205152014022000 | L31: =LEFT(RIGHT(K31, 4), 1) -> 2 | N31: 6 | O31: 1 | P31: =INDEX(Sheet2!A:A, MATCH(F31, Sheet2!B:B, 0)) -> 12 | Q31: 2 | R31: =INDEX(Sheet3!A:A, MATCH(G31, Sheet3!B:B, 0)) -> 4 | S31: 08123 | T31: =CONCATENATE(K31, ".jpg") -> 199205152014022000.jpg
A32: SUHADI ROHANI | B32: 197409152006041004 | C32: 9 | D32: 1974 | E32: III/b, TMT 01-04-2026 | F32: Pengelola Layanan Operasional | G32: SLTA | H32: =LEFT(E32, SEARCH(",",E32)-1) -> III/b | I32: 31 | J32: =A32 -> SUHADI ROHANI | K32: =""&B32 -> 197409152006041004 | L32: =LEFT(RIGHT(K32, 4), 1) -> 1 | N32: 6 | O32: 1 | P32: =INDEX(Sheet2!A:A, MATCH(F32, Sheet2!B:B, 0)) -> 20 | Q32: 2 | R32: =INDEX(Sheet3!A:A, MATCH(G32, Sheet3!B:B, 0)) -> 6 | S32: 08123 | T32: =CONCATENATE(K32, ".jpg") -> 197409152006041004.jpg
A33: IMAM SUPARDI, A.Md | B33: 1.9840806e+17 | C33: 8 | D33: 1984 | E33: III/a, TMT 01-10-2023 | F33: Pengolah Data dan Informasi | G33: DIII | H33: =LEFT(E33, SEARCH(",",E33)-1) -> III/a | I33: 32 | J33: =A33 -> IMAM SUPARDI, A.Md | K33: =""&B33 -> 198408062015031000 | L33: =LEFT(RIGHT(K33, 4), 1) -> 1 | N33: 6 | O33: 1 | P33: =INDEX(Sheet2!A:A, MATCH(F33, Sheet2!B:B, 0)) -> 9 | Q33: 2 | R33: =INDEX(Sheet3!A:A, MATCH(G33, Sheet3!B:B, 0)) -> 5 | S33: 08123 | T33: =CONCATENATE(K33, ".jpg") -> 198408062015031000.jpg
A34: EVI DARYANTI, A.Md. | B34: 199510242025062001 | C34: 10 | D34: 1995 | E34: II/c | F34: Arsiparis Keterampilan | G34: DIII | H34: =E34 -> II/c | I34: 33 | J34: =A34 -> EVI DARYANTI, A.Md. | K34: =""&B34 -> 199510242025062001 | L34: =LEFT(RIGHT(K34, 4), 1) -> 2 | N34: 6 | O34: 1 | P34: =INDEX(Sheet2!A:A, MATCH(F34, Sheet2!B:B, 0)) -> 22 | Q34: 2 | R34: =INDEX(Sheet3!A:A, MATCH(G34, Sheet3!B:B, 0)) -> 5 | S34: 08123 | T34: =CONCATENATE(K34, ".jpg") -> 199510242025062001.jpg
A35: BAGAS SANTOSA NUGRAHA, S.Tr.T. | B35: 200209112025061001 | C35: 9 | D35: 2002 | E35: III/a | F35: Teknisi Sarana dan Prasarana | G35: S1 | H35: =E35 -> III/a | I35: 34 | J35: =A35 -> BAGAS SANTOSA NUGRAHA, S.Tr.T. | K35: =""&B35 -> 200209112025061001 | L35: =LEFT(RIGHT(K35, 4), 1) -> 1 | N35: 6 | O35: 1 | P35: =INDEX(Sheet2!A:A, MATCH(F35, Sheet2!B:B, 0)) -> 23 | Q35: 2 | R35: =INDEX(Sheet3!A:A, MATCH(G35, Sheet3!B:B, 0)) -> 4 | S35: 08123 | T35: =CONCATENATE(K35, ".jpg") -> 200209112025061001.jpg
A36: LUTHFAN DARMAWAN, S.T. | B36: 200001122025061001 | C36: 11 | D36: 2000 | E36: III/a | F36: Teknisi Sarana dan Prasarana | G36: S1 | H36: =E36 -> III/a | I36: 35 | J36: =A36 -> LUTHFAN DARMAWAN, S.T. | K36: =""&B36 -> 200001122025061001 | L36: =LEFT(RIGHT(K36, 4), 1) -> 1 | N36: 6 | O36: 1 | P36: =INDEX(Sheet2!A:A, MATCH(F36, Sheet2!B:B, 0)) -> 23 | Q36: 2 | R36: =INDEX(Sheet3!A:A, MATCH(G36, Sheet3!B:B, 0)) -> 4 | S36: 08123 | T36: =CONCATENATE(K36, ".jpg") -> 200001122025061001.jpg
A37: AYU TRIANA SETYANINGRUM, A.Md. | B37: 199610112025062002 | C37: 10 | D37: 1996 | E37: II/c | F37: Pengelola Keprotokolan | G37: DIII | H37: =E37 -> II/c | I37: 36 | J37: =A37 -> AYU TRIANA SETYANINGRUM, A.Md. | K37: =""&B37 -> 199610112025062002 | L37: =LEFT(RIGHT(K37, 4), 1) -> 2 | N37: 6 | O37: 1 | P37: =INDEX(Sheet2!A:A, MATCH(F37, Sheet2!B:B, 0)) -> 24 | Q37: 2 | R37: =INDEX(Sheet3!A:A, MATCH(G37, Sheet3!B:B, 0)) -> 5 | S37: 08123 | T37: =CONCATENATE(K37, ".jpg") -> 199610112025062002.jpg
A38: THERESIA NATALIA SABU SUMA TUKAN, S.E. | B38: 199509152020122010 | C38: 9 | D38: 1995 | E38: III/b, TMT 01-11-2025 | F38: Pengelola pengadaan Barang/Jasa Pertama | G38: S1 | H38: =LEFT(E38, SEARCH(",",E38)-1) -> III/b | I38: 37 | J38: =A38 -> THERESIA NATALIA SABU SUMA TUKAN, S.E. | K38: =""&B38 -> 199509152020122010 | L38: =LEFT(RIGHT(K38, 4), 1) -> 2 | N38: 6 | O38: 5 | P38: =INDEX(Sheet2!A:A, MATCH(F38, Sheet2!B:B, 0)) -> 25 | Q38: 2 | R38: =INDEX(Sheet3!A:A, MATCH(G38, Sheet3!B:B, 0)) -> 4 | S38: 08123 | T38: =CONCATENATE(K38, ".jpg") -> 199509152020122010.jpg
A39: BURHAN ISLAMI A, S.I.Kom., M.A. | B39: 199505152019021003 | C39: 5 | D39: 1995 | E39: III/b, TMT 01-04-2023 | F39: Pranata Humas Ahli Muda | G39: S2 | H39: =LEFT(E39, SEARCH(",",E39)-1) -> III/b | I39: 38 | J39: =A39 -> BURHAN ISLAMI A, S.I.Kom., M.A. | K39: =""&B39 -> 199505152019021003 | L39: =LEFT(RIGHT(K39, 4), 1) -> 1 | N39: 6 | O39: 5 | P39: =INDEX(Sheet2!A:A, MATCH(F39, Sheet2!B:B, 0)) -> 19 | Q39: 2 | R39: =INDEX(Sheet3!A:A, MATCH(G39, Sheet3!B:B, 0)) -> 3 | S39: 08123 | T39: =CONCATENATE(K39, ".jpg") -> 199505152019021003.jpg
A40: MUHAMMAD FATCHAN HELVIAN, A.Md.Vet. | B40: 1.9971223e+17 | C40: 12 | D40: 1997 | E40: VII | F40: Arsiparis Terampil | G40: DIII | H40: =E40 -> VII | I40: 39 | J40: =A40 -> MUHAMMAD FATCHAN HELVIAN, A.Md.Vet. | K40: =""&B40 -> 199712232024211000 | L40: =LEFT(RIGHT(K40, 4), 1) -> 1 | N40: 6 | O40: 2 | P40: =INDEX(Sheet2!A:A, MATCH(F40, Sheet2!B:B, 0)) -> 26 | Q40: 2 | R40: =INDEX(Sheet3!A:A, MATCH(G40, Sheet3!B:B, 0)) -> 5 | S40: 08123 | T40: =CONCATENATE(K40, ".jpg") -> 199712232024211000.jpg
...

Sheet Sheet2
A1: id_jabatan | B1: jenis_jabatan
A2: 1 | B2: Kepala Kantor
A3: 2 | B3: Kepala Bagian Tata Usaha
A4: 3 | B4: Kasubag Kepegawaian
A5: 4 | B5: Analis Sumber Daya Manusia Aparatur Ahli Pertama
A6: 5 | B6: Penelaah Teknis Kebijakan
A7: 6 | B7: Arsiparis Penyelia
A8: 7 | B8: Analis Sumber Daya Manusia Aparatur Ahli Muda
A9: 8 | B9: Pranata SDM Mahir
A10: 9 | B10: Pengolah Data dan Informasi
A11: 10 | B11: Analis Sumber Daya Manusia Aparatur Ahli Pertama
A12: 11 | B12: Kasubag Perencanaan dan Keuangan
A13: 12 | B13: Arsiparis Ahli Pertama
... A58: 57 | B58: Penelaah Teknis Kebijakan

Sheet Sheet3
A1: id_gelar | B1: nama_gelar
A2: 1 | B2: Professor
A3: 2 | B3: S3
A4: 3 | B4: S2
A5: 4 | B5: S1
A6: 5 | B6: DIII
A7: 6 | B7: SMA
A8: 6 | B8: SMK
A9: 6 | B9: SLTA
A10: 7 | B10: SMP
A11: 8 | B11: SLTP

Sheet Sheet4
A1: id_gelar | B1: nama_gelar
A2: 1 | B2: I/A
A3: 2 | B3: I/B
A4: 3 | B4: I/C
A5: 4 | B5: I/D
A6: 5 | B6: II/A
A7: 6 | B7: II/B
A8: 7 | B8: II/C
A9: 8 | B9: II/D
A10: 9 | B10: III/A
A11: 10 | B11: III/B
A12: 11 | B12: III/C
A13: 12 | B13: III/D
... A35: 34 | B35: XVII

Sheet Sheet5
